<?xml version="1.0" ?>
<!-- =================================================================================== -->
<!-- |    This document was autogenerated by xacro from bravo_table.xacro              | -->
<!-- |    EDITING THIS FILE BY HAND IS NOT RECOMMENDED                                 | -->
<!-- =================================================================================== -->
<robot name="bravo_manipulation">
  <!-- Other Colors -->
  <material name="black">
    <color rgba="0.0 0.0 0.0 1.0"/>
  </material>
  <material name="blue">
    <color rgba="0.0 0.0 0.8 1.0"/>
  </material>
  <material name="teal">
    <color rgba="0.0 0.5 0.5 1.0"/>
  </material>
  <material name="green">
    <color rgba="0.0 0.8 0.0 1.0"/>
  </material>
  <material name="grey">
    <color rgba="0.2 0.2 0.2 1.0"/>
  </material>
  <material name="orange">
    <color rgba="1.0 0.4235294117647059 0.0392156862745098 0.5"/>
  </material>
  <material name="brown">
    <color rgba="0.8705882352941177 0.8117647058823529 0.7647058823529411 1.0"/>
  </material>
  <material name="red">
    <color rgba="0.8 0.0 0.0 1.0"/>
  </material>
  <material name="white">
    <color rgba="1.0 1.0 1.0 1.0"/>
  </material>
  <!-- See K&D properties: -->
  <!-- https://drive.google.com/file/d/1ip1LyPxuHns-bcfWcwyZzF57LlxkPQcj/view?usp=drive_link -->
  <!-- https://en.wikipedia.org/wiki/Denavit%E2%80%93Hartenberg_parameters#:~:text=handed%20coordinate%20system.-,Four%20parameters,-%5Bedit%5D -->
  <material name="bravo_black">
    <color rgba="0.3 0.3 0.3 1. "/>
  </material>

  <link name="ee_link"/>
  <joint name="ee_link_joint" type="fixed">
    <parent link="bravo_1023_1_joint_link"/>
    <child link="ee_link"/>
    <origin rpy="0 0 -1.5707" xyz="0 0 0.120"/>
  </joint>
  <link name="bravo_base_link">
    <inertial>
      <mass value="1.25"/>
      <origin xyz="-0.075 -0.006 -0.003"/>
      <inertia ixx="0.002108" ixy="0.00018199999999999998" ixz="-1.4999999999999999e-05" iyy="0.0025729999999999998" iyz="-2.1e-05" izz="0.003483"/>
    </inertial>
    <visual>
      <geometry>
        <mesh filename="package://bravo_description/meshes/RS2-1019_base.stl"/>
      </geometry>
      <material name="bravo_black"/>
      <origin rpy="0.0 -0.0 0.0" xyz="0.0 0.0 0.0"/>
    </visual>
    <collision>
      <geometry>
        <box size="0.0725 0.1112 0.083 "/>
      </geometry>
      <origin rpy="0.0 0.0 0.0" xyz="0.03625 0.0 0.0415"/>
    </collision>
    <collision>
      <geometry>
        <box size="0.05 0.08 0.06"/>
      </geometry>
      <origin rpy="0.0 0.0 0.0" xyz="0.025 -0.04556 0.03"/>
    </collision>
    <collision>
      <geometry>
        <cylinder length="0.083" radius="0.046"/>
      </geometry>
      <origin rpy="0.0 0.0 0.0" xyz="0.0665 0.0 0.0415"/>
    </collision>
  </link>
  <link name="bravo_1019_end_link">
    <inertial>
      <mass value="1.55"/>
      <inertia ixx="0.011441999999999999" ixy="-0.000484" ixz="0.003405" iyy="0.01298" iyz="-0.0012649999999999998" izz="0.003202"/>
      <origin xyz="0.005 -0.001 0.016"/>
    </inertial>
    <visual>
      <geometry>
        <mesh filename="package://bravo_description/meshes/RS2-1019_end.stl"/>
      </geometry>
      <material name="bravo_black"/>
      <origin rpy="0.0 -0.0 0.0" xyz="0.0 0.0 0.0"/>
    </visual>
    <visual>
      <geometry>
        <mesh filename="package://bravo_description/meshes/RS2-1013_base.stl"/>
      </geometry>
      <material name="bravo_black"/>
      <origin rpy="0.0 -0.0 0.0" xyz="0.0 0.0 0.0"/>
    </visual>
    <collision>
      <geometry>
        <mesh filename="package://bravo_description/meshes/RS2-1019_end.stl"/>
      </geometry>
      <origin rpy="0.0 -0.0 0.0" xyz="0.0 0.0 0.0"/>
    </collision>
    <collision>
      <geometry>
        <cylinder length="0.03" radius="0.046"/>
      </geometry>
      <origin rpy="0.0 -0.0 0.0" xyz="0.0 0.0 0.015"/>
    </collision>
    <collision>
      <geometry>
        <cylinder length="0.1" radius="0.046"/>
      </geometry>
      <origin rpy="1.5707 -0.0 0.0" xyz="0.048 0.0 0.0642"/>
    </collision>
  </link>
  <link name="bravo_1013_joint_link">
    <inertial>
      <mass value="1.14"/>
      <origin xyz="0.022 -0.029 0.001"/>
      <inertia ixx="0.0032129999999999997" ixy="-0.001548" ixz="-3.1e-05" iyy="0.002327" iyz="6e-06" izz="0.00434"/>
    </inertial>
    <visual>
      <geometry>
        <mesh filename="package://bravo_description/meshes/RS2-1013_end.stl"/>
      </geometry>
      <material name="bravo_black"/>
      <origin rpy="0.0 -0.0 0.0" xyz="0.0 0.0 0.0"/>
    </visual>
    <visual>
      <geometry>
        <mesh filename="package://bravo_description/meshes/RS2-1026_0_base.stl"/>
      </geometry>
      <material name="bravo_black"/>
      <origin rpy="3.14159 -0.0 3.14159" xyz="0.04600000000128156 4.829533423884964e-07 -0.2325499999993592"/>
    </visual>
    <visual>
      <geometry>
        <mesh filename="package://bravo_description/meshes/RS2-1030.stl"/>
      </geometry>
      <material name="bravo_black"/>
      <origin rpy="3.14159 -0.0 3.14159" xyz="0.046 0.0 -0.05055"/>
    </visual>
    <collision>
      <geometry>
        <cylinder length="0.03" radius="0.046"/>
      </geometry>
      <origin rpy="0.0 0.0 0.0" xyz="0.046 0.0 -0.03555"/>
    </collision>
    <collision>
      <geometry>
        <cylinder length="0.03" radius="0.0408"/>
      </geometry>
      <origin rpy="3.14159 -0.0 3.14159" xyz="0.04600000000138718 5.227571892886473e-07 -0.24754999999930644"/>
    </collision>
    <collision>
      <geometry>
        <cylinder length="0.0816" radius="0.0408"/>
      </geometry>
      <origin rpy="-1.5708953071795866 -0.0 3.14159" xyz="0.005200000001832204 7.445972960125356e-07 -0.29034999999915573"/>
    </collision>
    <collision>
      <geometry>
        <cylinder length="0.03033333" radius="0.046"/>
      </geometry>
      <origin rpy="3.14159 -0.0 3.14159" xyz="0.046000000000106796 4.0246094175109416e-08 -0.0657166599999466"/>
    </collision>
    <collision>
      <geometry>
        <cylinder length="0.03033333" radius="0.045"/>
      </geometry>
      <origin rpy="3.14159 -0.0 3.14159" xyz="0.04600000000032039 1.207383355971241e-07 -0.0960499999998398"/>
    </collision>
    <collision>
      <geometry>
        <cylinder length="0.03033333" radius="0.044"/>
      </geometry>
      <origin rpy="3.14159 -0.0 3.14159" xyz="0.04600000000053398 2.0123055844401027e-07 -0.126383332999733"/>
    </collision>
    <collision>
      <geometry>
        <cylinder length="0.03033333" radius="0.043"/>
      </geometry>
      <origin rpy="3.14159 -0.0 3.14159" xyz="0.046000000000747575 2.817227828830503e-07 -0.15671666659962621"/>
    </collision>
    <collision>
      <geometry>
        <cylinder length="0.03033333" radius="0.042"/>
      </geometry>
      <origin rpy="3.14159 -0.0 3.14159" xyz="0.04600000000096117 3.6221500679137236e-07 -0.18704999999951943"/>
    </collision>
    <collision>
      <geometry>
        <cylinder length="0.03033333" radius="0.041"/>
      </geometry>
      <origin rpy="3.14159 -0.0 3.14159" xyz="0.04600000000117476 4.427071420697953e-07 -0.21738329999941264"/>
    </collision>
  </link>
  <link name="bravo_1026_0_joint_link">
    <inertial>
      <origin rpy="0.0 -0.0 0.0" xyz="0.017 -0.026 -0.002"/>
      <mass value="1.14"/>
      <inertia ixx="0.021231999999999997" ixy="0.00033" ixz="-0.003738" iyy="0.022251999999999997" iyz="-0.0012779999999999998" izz="0.002054"/>
    </inertial>
    <visual>
      <geometry>
        <mesh filename="package://bravo_description/meshes/RS2-1026_0_end.stl"/>
      </geometry>
      <material name="bravo_black"/>
      <origin rpy="0.0 -0.0 0.0" xyz="0.0 0.0 0.0"/>
    </visual>
    <collision>
      <geometry>
        <cylinder length="0.08" radius="0.0408"/>
      </geometry>
      <origin rpy="0.0 0.0 0.0" xyz="0.0408 0.0 -0.05385"/>
    </collision>
  </link>
  <link name="bravo_1026_1_joint_link">
    <inertial>
      <mass value="1.03"/>
      <origin xyz="0.020 -0.024 0.001"/>
      <inertia ixx="0.00243" ixy="-0.001144" ixz="-3.9999999999999996e-05" iyy="0.002026" iyz="1.1e-05" izz="0.00333"/>
    </inertial>
    <visual>
      <geometry>
        <mesh filename="package://bravo_description/meshes/RS2-1026_1_end.stl"/>
      </geometry>
      <material name="bravo_black"/>
      <origin rpy="0.0 0.0 3.14159" xyz="0.0 0.0 0.0"/>
    </visual>
    <visual>
      <geometry>
        <mesh filename="package://bravo_description/meshes/RS2-1023_0_base.stl"/>
      </geometry>
      <material name="bravo_black"/>
      <origin rpy="0.0 -0.0 3.14159" xyz="0.0 0.0 0.0056"/>
    </visual>
    <collision>
      <geometry>
        <cylinder length="0.0056" radius="0.0408"/>
      </geometry>
      <origin rpy="0.0 0.0 3.14159" xyz="0.0 0.0 0.0028"/>
    </collision>
    <collision>
      <geometry>
        <cylinder length="0.03" radius="0.0408"/>
      </geometry>
      <origin rpy="0.0 -0.0 3.14159" xyz="0.0 0.0 0.0206"/>
    </collision>
    <collision>
      <geometry>
        <cylinder length="0.0816" radius="0.0408"/>
      </geometry>
      <origin rpy="1.5707 -0.0 3.14159" xyz="-0.040799999999856354 1.082664635687914e-07 0.0634"/>
    </collision>
  </link>
  <link name="bravo_1023_0_joint_link">
    <inertial>
      <origin rpy="0.0 -0.0 0.0" xyz="0.0 0.003 -0.098"/>
      <mass value="0.333"/>
      <inertia ixx="0.003709" ixy="-2e-06" ixz="-4e-06" iyy="0.003734" iyz="0.0" izz="7.9e-05"/>
    </inertial>
    <visual>
      <geometry>
        <mesh filename="package://bravo_description/meshes/RS2-1023_0_end.stl"/>
      </geometry>
      <material name="bravo_black"/>
      <origin rpy="0.0 -0.0 0.0" xyz="0.0 0.0 0.0"/>
    </visual>
    <collision>
      <geometry>
        <cylinder length="0.08" radius="0.0408"/>
      </geometry>
      <origin rpy="0.0 0.0 0.0" xyz="0.0408 0.0 -0.05385"/>
    </collision>
  </link>
  <link name="bravo_1023_1_joint_link">
    <inertial>
      <origin xyz="0.0 0.003 -0.098"/>
      <mass value="1.04"/>
      <inertia ixx="0.022359" ixy="1e-06" ixz="-1.8999999999999998e-05" iyy="0.022362999999999997" iyz="1.4999999999999999e-05" izz="0.000936"/>
    </inertial>
    <visual>
      <geometry>
        <mesh filename="package://bravo_description/meshes/RS2-1023_1_end.stl"/>
      </geometry>
      <material name="bravo_black"/>
      <origin rpy="0.0 -0.0 0.0" xyz="0.0 0.0 0.0"/>
    </visual>
    <visual>
      <geometry>
        <mesh filename="package://bravo_description/meshes/RS2-1028.stl"/>
      </geometry>
      <material name="bravo_black"/>
      <origin rpy="0.0 -0.0 0.0" xyz="0.0 0.0 0.0056"/>
    </visual>
    <collision>
      <geometry>
        <cylinder length="0.0056" radius="0.0408"/>
      </geometry>
      <origin rpy="0.0 0.0 0.0" xyz="0.0 0.0 0.0028"/>
    </collision>
    <collision>
      <geometry>
        <cylinder length="0.12" radius="0.0408"/>
      </geometry>
      <origin rpy="0.0 -0.0 0.0" xyz="0.0 0.0 0.06559999999999999"/>
    </collision>
  </link>
  <link name="bravo_push_rod">
    <inertial>
      <origin rpy="0.0 -0.0 0.0" xyz="0.0 0.0 0.0"/>
      <mass value="0.1"/>
      <inertia ixx="0.0001" ixy="0.0" ixz="0.0" iyy="0.0001" iyz="0.0" izz="0.0001"/>
    </inertial>
  </link>
  <joint name="bravo_axis_g" type="revolute">
    <dynamics damping="10.0" friction="0.0"/>
    <limit effort="500.0" lower="0.0" upper="6.2" velocity="6.0"/>
    <parent link="bravo_base_link"/>
    <child link="bravo_1019_end_link"/>
    <axis xyz=" 0.  0. -1."/>
    <origin rpy="0.0 0.0 3.14159" xyz="0.0665 0.0 0.08"/>
  </joint>
  <joint name="bravo_axis_a" type="prismatic">
    <dynamics damping="10.0" friction="0.0"/>
    <limit effort="1000.0" lower="0.0" upper="0.035" velocity="10.0"/>
    <parent link="bravo_1023_1_joint_link"/>
    <child link="bravo_push_rod"/>
    <axis xyz="0. 0. 1."/>
    <origin rpy="-1.5707 -1.5706999999997038 0.0" xyz="-8.669411487068951e-07 0.008999999958245167 0.12560000008350966"/>
  </joint>
  <joint name="bravo_axis_b" type="continuous">
    <dynamics damping="10.0" friction="0.0"/>
    <limit effort="500.0" velocity="6.0"/>
    <parent link="bravo_1023_0_joint_link"/>
    <child link="bravo_1023_1_joint_link"/>
    <axis xyz=" 0.  0. -1."/>
    <origin rpy="3.14159 -0.0 0.0" xyz="0.0408 -1.326794896676365e-09 -0.09434999999999824"/>
  </joint>
  <joint name="bravo_axis_c" type="revolute">
    <dynamics damping="10.0" friction="0.0"/>
    <limit effort="500.0" lower="0.0" upper="3.14" velocity="6.0"/>
    <parent link="bravo_1026_1_joint_link"/>
    <child link="bravo_1023_0_joint_link"/>
    <axis xyz=" 0. -1.  0."/>
    <origin rpy="0.0 -0.0 3.14159" xyz="-0.041999999999852135 1.1145077132081467e-07 0.0634"/>
  </joint>
  <joint name="bravo_axis_d" type="revolute">
    <dynamics damping="10.0" friction="0.0"/>
    <limit effort="500.0" lower="0.0" upper="6.2" velocity="6.0"/>
    <parent link="bravo_1026_0_joint_link"/>
    <child link="bravo_1026_1_joint_link"/>
    <axis xyz=" 0.  0. -1."/>
    <origin rpy="3.14159 -0.0 0.0" xyz="0.0408 -1.326794896676365e-09 -0.09434999999999824"/>
  </joint>
  <joint name="bravo_axis_e" type="revolute">
    <dynamics damping="10.0" friction="0.0"/>
    <limit effort="500.0" lower="0.0" upper="3.14" velocity="6.0"/>
    <parent link="bravo_1013_joint_link"/>
    <child link="bravo_1026_0_joint_link"/>
    <axis xyz=" 0. -1.  0."/>
    <origin rpy="3.14159 -0.0 3.14159" xyz="0.0040000000018364235 7.477816037645589e-07 -0.29034999999915573"/>
  </joint>
  <joint name="bravo_axis_f" type="revolute">
    <dynamics damping="10.0" friction="0.0"/>
    <limit effort="500.0" lower="0.0" upper="3.14" velocity="6.0"/>
    <parent link="bravo_1019_end_link"/>
    <child link="bravo_1013_joint_link"/>
    <axis xyz=" 0. -1.  0."/>
    <origin rpy="0.0 -0.0 0.0" xyz="0.046 0.0 0.0642"/>
  </joint>
</robot>
